Workbook

Sheet README
A2: Enterprise AI Governance Operating Framework (AIGOF)
A3: README — Start Here
B5: Purpose
B6: A complete, audit-ready toolkit to assess, govern, and operate AI systems against NIST AI RMF, ISO/IEC 42001, and the EU AI Act — with the operational artifacts (inventory, risk register, controls library, KPIs, committee governance) needed to actually run a program, not just assess one.
B8: Who should use it
B9: AI Governance & Risk teams (assessment, controls, KPIs); Internal Audit (checklists, evidence catalog); Program Management (operating model, RACI, decision log); Product & Data Science (model cards, SDLC, guardrails); Compliance & Privacy (EU AI Act, GDPR, state-law tracking, sector packs).
B11: How to use it — recommended flow
B12: 1. Operating Model — understand the end-to-end governance flow and stage ownership.
B13: 2. AI Inventory — catalog your AI systems and assign risk tiers.
B14: 3. Gap Assessment — work the Master Crosswalk + framework checklists for in-scope systems.
B15: 4. Risk Register — capture gaps as risks with owners and residual ratings.
B16: 5. Controls Library — map which controls address each risk; track implementation.
B17: 6. Evidence Catalog — gather the artifacts that prove each control operates.
B18: 7. Dashboard & Maturity — roll up status, KPIs, and maturity for leadership.
B20: What each worksheet is for
B21: Worksheet Group | C21: Purpose
B22: Dashboard | C22: Executive roll-up: coverage, KPIs, maturity, heatmaps
B23: Operating Model / Lifecycle View | C23: End-to-end governance flow mapped to owners, frameworks, controls
B24: Master Crosswalk | C24: NIST x ISO x EU AI Act, the analytical heart of the toolkit
B25: Framework Assessments & Audit Checklists | C25: Detailed testable questions per framework
B26: Responsible AI / Guardrails / GenAI Controls | C26: Principle- and control-level checks incl. GenAI & agentic
B27: Data / Model Gov, SDLC, Program Mgmt | C27: Operational governance across the lifecycle
B28: Inventory / Risk / Controls / RACI / Decision Log / KPI / Maturity | C28: Core operating artifacts to run the program
B29: Evidence Catalog / Model Card / Incident / Exception / Vendor | C29: Audit-facing artifacts and registers
B30: GDPR / State Laws / Sector Packs / Financial Services | C30: Compliance and sector-specific overlays
B31: Framework Reference | C31: Appendix: what every cited clause/article/principle means
B33: Important: This is a professional assessment instrument, not a certification or legal advice. The US State AI Laws tab is time-sensitive — re-verify before relying on it. Confirm sector/privacy specifics with qualified counsel.

Sheet Cover & Instructions
A2: Enterprise AI Governance Operating Framework (AIGOF) & Gap Assessment
A3: NIST AI RMF 1.0 x ISO/IEC 42001 x EU AI Act
B5: Purpose
B6: This workbook provides a structured, audit-ready crosswalk between the NIST AI Risk Management Framework (AI RMF 1.0), ISO/IEC 42001:2023 (AI Management System), and the EU AI Act — anchored to NIST's full set of 72 published subcategories across the Govern, Map, Measure, and Manage functions.
B8: How this is built
B9: This is a full enterprise AI governance audit toolkit organized in three layers. FRAMEWORK LAYER (tabs 3-8): the executive crosswalk plus detailed audit checklists for NIST AI RMF, EU AI Act, and ISO/IEC 42001. RESPONSIBLE-AI & GUARDRAILS LAYER (tabs 9-10): Responsible AI principles and technical guardrails across input/model/output/operational controls. OPERATIONAL LAYER (tabs 11-15): Data Governance, Model Governance, AI SDLC (controls by lifecycle phase), AI Program Management (RAID & KPIs), and a region-neutral Financial Services pack. The Dashboard rolls up every tab and includes an executive KPI panel and a 1-5 maturity scale.
B12: Tabs in this workbook
B13: 1-2. Cover & Dashboard (with KPI panel + maturity scale)
B14: 3-5. Executive Crosswalk — NIST / EU AI Act / ISO 42001 (140 items)
B15: 6-8. Detailed Audit Checklists — testable questions per framework (~361 items)
B16: 9-10. Responsible AI & Guardrails — principles + technical guardrail controls
B17: 11-15. Operational Layer — Data Gov, Model Gov, AI SDLC, Program Mgmt, Financial Services
B18: 16. Framework Reference — extended legend (frameworks, RAI principles, guardrail taxonomy, MRM concepts)
B19: How to use it
... B26: Document Control
B27: Document Owner: | C27: [ Your Name ]
B28: Version: | C28: 9.0
B29: Last Updated: | C29: [ date ]
B30: Classification: | C30: Confidential — Portfolio / Client Deliverable
B31: Review Cycle: | C31: Quarterly
B33: Version History
B34: Version | C34: Summary of Changes
B35: 1.0 | C35: Initial 4-tab crosswalk (NIST-anchored)
B36: 2.0 | C36: Added full EU AI Act & ISO 42001 assessment tabs
B37: 3.0 | C37: Added detailed audit checklists (testable questions)
B38: 4.0 | C38: Added Responsible AI & technical guardrails
B39: 5.0 | C39: Added operational layer: Data/Model Gov, SDLC, Program Mgmt, Financial Services; KPI dashboard
B40: 6.0 | C40: Added operational artifacts (inventory, risk register, controls library, RACI, decision log, KPI catalog, maturity), sector packs, US state-law tracker, GDPR checklist, lifecycle view; split RAI/Guardrails

Sheet Executive Summary
A1: Executive Summary — AI Governance Program
A3: Current State — Key Metrics
B4: AI Systems in Inventory | C4: =COUNTA('AI Inventory'!A3:A40) -> 3 | E4: Open Risks | F4: =COUNTIF('AI Risk Register'!J3:J200,"Open") -> 3
B5: AI Systems in Production | C5: =COUNTIF('AI Inventory'!L3:L40,"Live") -> 3 | E5: Critical/High Open Risks | F5: =COUNTIFS('AI Risk Register'!F3:F200,"Critical",'AI Risk Register'!J3:J200,"Open")+COUNTIFS('AI Risk Register'!F3:F200,"High",'AI Risk Register'!J3:J200,"Open") -> 3
B6: High / Critical Risk Systems | C6: =COUNTIF('AI Inventory'!K3:K40,"High")+COUNTIF('AI Inventory'!K3:K40,"Critical") -> 2 | E6: Overall Maturity (of 5) | F6: ='Maturity Assessment'!D16 -> 2.5
A8: Top Risks (enter your top items)
B9: # | C9: Top Risk
B10: 1
B11: 2
B12: 3
B13: 4
B14: 5
A16: Top Recommendations
B17: # | C17: Recommendation
B18: 1
B19: 2
B20: 3
B21: 4
B22: 5
A24: 30 / 60 / 90-Day Roadmap
B25: 30 Days | D25: 60 Days | F25: 90 Days
B26: Charter, inventory kickoff | D26: Gap assessment, risk register | F26: Controls, KPIs, first committee review
B31: Note: metric cells are live-linked to the Inventory, Risk Register, and Maturity tabs. Blue cells are for narrative entry.

Sheet Dashboard
A1: Executive Dashboard — Gap Assessment Summary
A3: Total Requirements Assessed (All 3 Tabs) | B3: =COUNTA('Master Crosswalk'!D3:D74)+COUNTA('EU AI Act Full Assessment'!C3:C37)+COUNTA('ISO 42001 Full Assessment'!C3:C35) -> 140 | E3: Overall Maturity
A4: NIST AI RMF Subcategories | B4: =COUNTA('Master Crosswalk'!D3:D74) -> 72 | E4: ='Maturity Assessment'!D16 -> 2.5
A5: EU AI Act Articles | B5: =COUNTA('EU AI Act Full Assessment'!C3:C37) -> 35 | E5: out of 5.0
A6: ISO/IEC 42001 Clauses & Controls | B6: =COUNTA('ISO 42001 Full Assessment'!C3:C35) -> 33
A7: Complete (All Tabs) | B7: =COUNTIF('Master Crosswalk'!O3:O74,"Complete")+COUNTIF('EU AI Act Full Assessment'!L3:L37,"Complete")+COUNTIF('ISO 42001 Full Assessment'!I3:I35,"Complete") -> 0
A8: % Complete | B8: =B7/B3 -> 0
A10: Total Detailed Audit Questions (4 Checklist Tabs) | B10: =COUNTA('Audit Checklist - NIST'!F3:F153)+COUNTA('Audit Checklist - EU AI Act'!F3:F108)+COUNTA('Audit Checklist - ISO 42001'!F3:F106)+COUNTA('responsible ai & guardrails'!d3:d59) -> 362
A11: NIST Crosswalk — By Domain
A12: Domain | B12: # Requirements | C12: Critical/High Risk | D12: % Complete
A13: Governance & Policy | B13: =COUNTIF('Master Crosswalk'!B3:B74,"Governance & Policy") -> 19 | C13: =COUNTIFS('Master Crosswalk'!B3:B74,"Governance & Policy",'Master Crosswalk'!K3:K74,"Critical")+COUNTIFS('Master Crosswalk'!B3:B74,"Governance & Policy",'Master Crosswalk'!K3:K74,"High") -> 3 | D13: =IFERROR(COUNTIFS('Master Crosswalk'!B3:B74,"Governance & Policy",'Master Crosswalk'!O3:O74,"Complete")/COUNTIF('Master Crosswalk'!B3:B74,"Governance & Policy"),0) -> 0
A14: Risk Identification (Map) | B14: =COUNTIF('Master Crosswalk'!B3:B74,"Risk Identification (Map)") -> 18 | C14: =COUNTIFS('Master Crosswalk'!B3:B74,"Risk Identification (Map)",'Master Crosswalk'!K3:K74,"Critical")+COUNTIFS('Master Crosswalk'!B3:B74,"Risk Identification (Map)",'Master Crosswalk'!K3:K74,"High") -> 0 | D14: =IFERROR(COUNTIFS('Master Crosswalk'!B3:B74,"Risk Identification (Map)",'Master Crosswalk'!O3:O74,"Complete")/COUNTIF('Master Crosswalk'!B3:B74,"Risk Identification (Map)"),0) -> 0
A15: Testing & Measurement (Measure) | B15: =COUNTIF('Master Crosswalk'!B3:B74,"Testing & Measurement (Measure)") -> 22 | C15: =COUNTIFS('Master Crosswalk'!B3:B74,"Testing & Measurement (Measure)",'Master Crosswalk'!K3:K74,"Critical")+COUNTIFS('Master Crosswalk'!B3:B74,"Testing & Measurement (Measure)",'Master Crosswalk'!K3:K74,"High") -> 0 | D15: =IFERROR(COUNTIFS('Master Crosswalk'!B3:B74,"Testing & Measurement (Measure)",'Master Crosswalk'!O3:O74,"Complete")/COUNTIF('Master Crosswalk'!B3:B74,"Testing & Measurement (Measure)"),0) -> 0
A16: Risk Treatment (Manage) | B16: =COUNTIF('Master Crosswalk'!B3:B74,"Risk Treatment (Manage)") -> 13 | C16: =COUNTIFS('Master Crosswalk'!B3:B74,"Risk Treatment (Manage)",'Master Crosswalk'!K3:K74,"Critical")+COUNTIFS('Master Crosswalk'!B3:B74,"Risk Treatment (Manage)",'Master Crosswalk'!K3:K74,"High") -> 0 | D16: =IFERROR(COUNTIFS('Master Crosswalk'!B3:B74,"Risk Treatment (Manage)",'Master Crosswalk'!O3:O74,"Complete")/COUNTIF('Master Crosswalk'!B3:B74,"Risk Treatment (Manage)"),0) -> 0
A19: By Framework
A20: Framework | B20: # Items | C20: % Complete
A21: NIST AI RMF | B21: =COUNTA('Master Crosswalk'!D3:D74) -> 72 | C21: =IFERROR(COUNTIF('Master Crosswalk'!O3:O74,"Complete")/COUNTA('Master Crosswalk'!D3:D74),0) -> 0
A22: EU AI Act | B22: =COUNTA('EU AI Act Full Assessment'!C3:C37) -> 35 | C22: =IFERROR(COUNTIF('EU AI Act Full Assessment'!L3:L37,"Complete")/COUNTA('EU AI Act Full Assessment'!C3:C37),0) -> 0
A23: ISO/IEC 42001 | B23: =COUNTA('ISO 42001 Full Assessment'!C3:C35) -> 33 | C23: =IFERROR(COUNTIF('ISO 42001 Full Assessment'!I3:I35,"Complete")/COUNTA('ISO 42001 Full Assessment'!C3:C35),0) -> 0
A26: NIST Crosswalk — By Risk Rating
A27: Risk Rating | B27: Count
A28: Critical | B28: =COUNTIF('Master Crosswalk'!K3:K74,"Critical") -> 1
A29: High | B29: =COUNTIF('Master Crosswalk'!K3:K74,"High") -> 2
A30: Medium | B30: =COUNTIF('Master Crosswalk'!K3:K74,"Medium") -> 2
A31: Low | B31: =COUNTIF('Master Crosswalk'!K3:K74,"Low") -> 1
A34: Executive KPIs (auto-calculated from tabs; blue = manual entry)
A35: Metric | B35: Value | C35: Target / Note
A36: AI systems in production | B36: =COUNTIF('AI Inventory'!L3:L40,"Live") -> 3 | C36: Live from AI Inventory
A37: High-risk AI systems | B37: =COUNTIF('AI Inventory'!K3:K40,"High")+COUNTIF('AI Inventory'!K3:K40,"Critical") -> 2 | C37: Live from AI Inventory
A38: AI inventory coverage (%) | B38: =IFERROR(COUNTA('AI Inventory'!A3:A40)/COUNTA('AI Inventory'!A3:A40),1) -> 1 | C38: % of inventoried systems
A39: Open P1 findings | B39: =COUNTIFS('AI Risk Register'!F3:F200,"Critical",'AI Risk Register'!J3:J200,"Open")+COUNTIFS('AI Risk Register'!F3:F200,"High",'AI Risk Register'!J3:J200,"Open") -> 3 | C39: Live from Risk Register
A40: Open audit issues | C40: Track to closure
A41: Average maturity score (1-5) | B41: =IFERROR(AVERAGE('Maturity Assessment'!B3:B12),"—") -> 2.5 | C41: Live avg from Maturity tab
A42: AI incidents (last 12 mo) | B42: =COUNTA('AI Incident Register'!A3:A50) -> 3 | C42: Live from Incident Register
A43: Mean time to remediate (days) | C43: Lower is better
A44: Drift events (last 12 mo) | B44: =COUNTIF('AI Incident Register'!D3:D200,"Drift") -> 1 | C44: Live from Incident Register
A45: Hallucination rate (%) — GenAI | C45: Where measured
A47: Maturity Scale
A48: 1 — Initial | B48: Ad hoc, undocumented, reactive
A49: 2 — Developing | B49: Some processes exist but inconsistent
...

Sheet Operating Model
A1: AI Governance Operating Model — End-to-End Flow
A2: Stage | B2: Owner | C2: Key Deliverables | D2: Frameworks | E2: Controls | F2: Outputs
A3: Business Strategy | B3: Exec / Board | C3: AI ambition, risk appetite | D3: NIST GOVERN | E3: GOV-01, GOV-02 | F3: Approved AI strategy
A4: AI Portfolio | B4: AI Governance | C4: Portfolio view, prioritization | D4: ISO Cl.6 | E4: GOV-02 | F4: Prioritized backlog
A5: AI Intake | B5: AI Governance | C5: Intake form, business case | D5: NIST MAP 1 | E5: GOV-06 | F5: Registered request
A6: Risk Classification | B6: AI Governance | C6: Risk tier decision | D6: EU Art.6; NIST MAP | E6: GOV-04, MOD-07 | F6: Risk tier + Annex III flag
A7: Gap Assessment | B7: AI Gov / Audit | C7: Gap analysis vs frameworks | D7: NIST/ISO/EU | E7: (all checklists) | F7: Gap report + remediation
A8: Governance Committee | B8: Steering Committee | C8: Go/No-Go, exceptions, risk acceptance | D8: NIST GOVERN 2.3 | E8: GOV-04, GOV-07 | F8: Decision log entry
A9: Development | B9: Data Science | C9: Model build, data prep | D9: EU Art.10; ISO 8.3 | E9: DAT-01, MOD-02 | F9: Model + documentation
A10: Testing | B10: QA / Data Science | C10: Bias, explainability, security | D10: NIST MEASURE; EU Art.15 | E10: MOD-07, TST-01..04, SEC-04 | F10: Test reports
A11: Go / No-Go | B11: AI Governance | C11: Deployment approval | D11: ISO 8.1; SR 11-7 | E11: DEP-01 | F11: Signed approval
A12: Deployment | B12: MLOps | C12: Release with rollback | D12: EU Art.43-48 | E12: DEP-02, DEP-03 | F12: Live system
A13: Monitoring | B13: MLOps | C13: Drift, performance, incidents | D13: EU Art.72; ISO 9.1 | E13: MON-01..04 | F13: Monitoring dashboards
... A16: Retirement | B16: AI Governance | C16: Decommission, data disposal | D16: ISO A.6.2.6; EU Art.12 | E16: RET-01..03 | F16: Retirement record
A18: Flow: Strategy → Portfolio → Intake → Risk Classification → Gap Assessment → Committee → Development → Testing → Go/No-Go → Deployment → Monitoring → Audit → PDCA → Retirement

Sheet Lifecycle View
A1: AI Lifecycle View — Controls Mapped by Stage
A2: Stage | B2: What Happens | C2: ISO/IEC 42001 | D2: NIST AI RMF | E2: EU AI Act | F2: Responsible AI | G2: Key Guardrails / Controls
A3: 1. AI Strategy | B3: Set AI ambition, risk appetite, governance operating model | C3: Cl. 4-6 (context, leadership, planning) | D3: GOVERN 1-4 | E3: Art. 4 (AI literacy) | F3: Accountability | G3: Governance charter; risk appetite statement
A4: 2. AI Intake | B4: Capture request, business case, initial screen | C4: Cl. 6.1; A.6.2 | D4: MAP 1.1-1.2 | E4: Art. 6 (classification trigger) | F4: Accountability | G4: Intake form; shadow-AI discovery
A5: 3. Risk Classification | B5: Tier the system by risk | C5: Cl. 6.1 | D5: MAP 1.5, 2.1 | E5: Art. 6 & Annex III | F5: Fairness (screen) | G5: Risk classification gate (C-003)
A6: 4. Gap Assessment | B6: Assess against frameworks; find gaps | C6: Cl. 9.1-9.2 | D6: All functions | E6: Art. 9 | F6: All principles | G6: Gap tabs; controls library
A7: 5. Controls Design | B7: Select and design controls | C7: Cl. 8.1; Annex A | D7: MANAGE 1 | E7: Art. 9(5) | F7: Human Oversight | G7: Controls library; guardrail design
A8: 6. Development | B8: Build model; source & prep data | C8: Cl. 8.3; A.7 | D8: MAP 2.2 | E8: Art. 10 (data) | F8: Privacy, Fairness | G8: Secure-ML; data quality; PII controls
A9: 7. Testing | B9: Bias, explainability, security, robustness | C9: Cl. 8.3 | D9: MEASURE 2.x | E9: Art. 15 | F9: Fairness, Explainability, Security | G9: Bias test (C-004); adversarial testing
A10: 8. Deployment | B10: Go/No-Go; release with rollback | C10: Cl. 8.1 | D10: MANAGE 1 | E10: Art. 43-48 (conformity, CE) | F10: Accountability | G10: Approval gate (C-012); rollback; kill switch
A11: 9. Monitoring | B11: Drift, performance, incidents in production | C11: Cl. 9.1 | D11: MEASURE 2.12, 3.1; MANAGE 4 | E11: Art. 72 (post-market) | F11: Reliability | G11: Drift monitoring (C-007); alerting
A12: 10. Incident Response | B12: Detect, respond, report incidents | C12: A.6.2.8 | D12: MANAGE 2.3 | E12: Art. 73 (serious incident) | F12: Accountability | G12: IR runbook (C-008); escalation
A13: 11. Audit | B13: Independent review of the system & program | C13: Cl. 9.2 | D13: GOVERN 1.5 | E13: Art. 17 (QMS) | F13: Accountability | G13: Audit checklists; controls library
A14: 12. Retirement | B14: Decommission; dispose of data | C14: A.6.2.6 | D14: MANAGE 1.4 | E14: Art. 12 (records retention) | F14: Privacy | G14: Decommissioning process; data disposal

Sheet Governance Roadmap
A1: AI Governance Implementation Roadmap
A2: Phase | B2: Deliverable | C2: Owner | D2: Duration | E2: Dependencies | F2: Target Date | G2: Status
A3: Phase 1 — Governance Foundation | B3: AI governance charter, policy, committee stood up | C3: AI Governance | D3: 4-6 wks | E3: Executive sponsorship | G3: Not Started
A4: Phase 2 — AI Inventory | B4: Complete tiered inventory of AI systems | C4: Model Risk | D4: 4-8 wks | E4: Phase 1; discovery scan | G4: Not Started
A5: Phase 3 — Gap Assessment | B5: Framework crosswalk assessment for in-scope systems | C5: AI Gov / Audit | D5: 6-10 wks | E5: Phase 2 inventory | G5: Not Started
A6: Phase 4 — Controls Design & Build | B6: Controls library mapped and implemented | C6: AI Governance | D6: 8-12 wks | E6: Phase 3 gaps | G6: Not Started
A7: Phase 5 — Testing & Validation | B7: Bias, explainability, security testing embedded | C7: QA / Data Science | D7: 6-10 wks | E7: Phase 4 controls | G7: Not Started
A8: Phase 6 — Monitoring & Operations | B8: Drift/performance monitoring and KPIs live | C8: MLOps | D8: 6-8 wks | E8: Phase 5; tooling | G8: Not Started
A9: Phase 7 — Audit & Continuous Improvement | B9: First internal audit cycle; PDCA loop | C9: Internal Audit | D9: Ongoing | E9: Phases 1-6 | G9: Not Started
A11: Durations are indicative and scale with organization size and AI footprint. Phases can overlap; Phase 7 is continuous.

Sheet Stage Gates
A1: AI Governance Stage Gates
A2: Gate | B2: Entry Criteria | C2: Exit Criteria | D2: Gate Owner | E2: Key Evidence | F2: Decision
A3: G1 — Intake | B3: Business case submitted; owner assigned | C3: AI system risk-classified; registered in inventory | D3: AI Governance | E3: Intake form; risk tier
A4: G2 — Design | B4: Risk classification complete | C4: Architecture reviewed; controls & guardrails identified | D4: AI Governance | E4: Design doc; control mapping
A5: G3 — Development | B5: Controls & data requirements defined | C5: Model built; documentation & data quality signed off | D5: Data Science | E5: Model card; data quality report
A6: G4 — Testing | B6: Model build complete | C6: Bias/explainability/security test evidence complete | D6: QA | E6: Test reports
A7: G5 — Go/No-Go | B7: Testing complete | C7: Deployment approved; rollback plan in place | D7: Governance Committee | E7: Approval record; rollback plan
A8: G6 — Production | B8: Deployment approved | C8: Monitoring live; operational handoff complete | D8: MLOps | E8: Monitoring dashboards
A9: G7 — Periodic Review | B9: System in production | C9: Reassessed; continue / remediate / retire decision | D9: AI Governance | E9: Review record
A11: Each gate is a formal go/no-go checkpoint. A system cannot proceed to the next stage until exit criteria are met and the gate owner records a decision.

Sheet Framework Mapping Matrix
A1: Framework Mapping Matrix — Why Multiple Frameworks Work Together
A2: Governance Activity | B2: ISO/IEC 42001 | C2: NIST AI RMF | D2: EU AI Act | E2: Responsible AI | F2: Guardrails
A3: AI Strategy & Governance | B3: ✓ | C3: ✓ | E3: ✓
A4: AI Intake / Registration | B4: ✓ | C4: ✓ | D4: ✓
A5: Risk Classification | B5: ✓ | C5: ✓ | D5: ✓
A6: Risk Assessment | B6: ✓ | C6: ✓ | D6: ✓
A7: Data Governance | B7: ✓ | C7: ✓ | D7: ✓ | E7: ✓
A8: Bias / Fairness Testing | C8: ✓ | D8: ✓ | E8: ✓
A9: Explainability | C9: ✓ | D9: ✓ | E9: ✓
A10: Human Oversight | B10: ✓ | C10: ✓ | D10: ✓ | E10: ✓ | F10: ✓
A11: Security / Robustness | B11: ✓ | C11: ✓ | D11: ✓ | F11: ✓
A12: Privacy / Data Protection | B12: ✓ | D12: ✓ | E12: ✓ | F12: ✓
A13: Testing & Validation | B13: ✓ | C13: ✓ | D13: ✓ | F13: ✓
A14: Deployment / Go-No-Go | B14: ✓ | C14: ✓ | D14: ✓ | F14: ✓
A15: Monitoring / Drift | B15: ✓ | C15: ✓ | D15: ✓ | F15: ✓
A16: Incident Response | B16: ✓ | C16: ✓ | D16: ✓ | F16: ✓
A17: Transparency / Disclosure | C17: ✓ | D17: ✓ | E17: ✓
A18: Vendor / Third-Party | B18: ✓ | C18: ✓ | D18: ✓
A19: Audit & Assurance | B19: ✓ | C19: ✓ | D19: ✓
A20: Retirement / Decommission | B20: ✓ | C20: ✓ | D20: ✓
A22: Read across a row to see which frameworks govern each activity. Human Oversight, for example, is required by all — which is why a single-framework approach leaves gaps. This is the rationale for the crosswalk.

Sheet Master Crosswalk
A1: Master Crosswalk & Gap Assessment — NIST AI RMF x ISO/IEC 42001 x EU AI Act
A2: # | B2: Domain | C2: NIST Function | D2: NIST ID | E2: Requirement (Paraphrased) | F2: ISO/IEC 42001 Reference | G2: EU AI Act Reference | H2: Current State | I2: Evidence | J2: Gap Identified | K2: Risk Rating | L2: Recommendation | M2: Owner | N2: Priority | O2: Status
A3: 1 | B3: Governance & Policy | C3: GOVERN | D3: 1.1 | E3: Legal and regulatory requirements involving AI (incl. sector rules) are identified, tracked, and reflected in policy. | F3: Clause 4.1/4.2 - Context of the organization | G3: Art. 2, Art. 6 & Annex III - Scope & classification | H3: Formal AI regulatory tracker exists; updated quarterly by Compliance | I3: AI Regulatory Tracker v2.1, Compliance SharePoint | J3: Tracker does not yet include EU AI Act Annex III triggers for credit scoring | K3: High | L3: Add EU AI Act high-risk triggers to tracker; assign Compliance owner | M3: J. Alvarez, Compliance | N3: P2 | O3: In Progress
A4: 2 | B4: Governance & Policy | C4: GOVERN | D4: 1.2 | E4: Characteristics of trustworthy AI (valid, reliable, safe, secure, resilient, accountable, transparent, explainable, fair, privacy-enhanced) are embedded into organizational policy and SOPs. | F4: Clause 5.2 - AI Policy | G4: Art. 9 - Risk management system | H4: Responsible AI Principles published; not yet embedded in SDLC checklists | I4: Responsible AI Policy v1.0 | J4: Policy exists but engineering SDLC checklist has no AI-specific gate | K4: High | L4: Add AI trustworthiness gate to SDLC checklist | M4: M. Chen, Engineering | N4: P1 | O4: Not Started
A5: 3 | B5: Governance & Policy | C5: GOVERN | D5: 1.3 | E5: AI risk management processes are integrated into system design, development, deployment, evaluation, and decommissioning, calibrated to organizational risk appetite. | F5: Clause 6.1 - Actions to address risks/opportunities | G5: Art. 9 - Risk management system | H5: AI risk process defined for new model builds only | I5: Model Risk Policy MRM-014 | J5: No process for AI risk review of vendor/third-party AI tools | K5: Medium | L5: Extend AI risk process to cover third-party AI tools | M5: R. Osei, Model Risk | N5: P2 | O5: Remediation Planned
A6: 4 | B6: Governance & Policy | C6: GOVERN | D6: 1.4 | E6: Risk management processes and outcomes are documented and made available through transparency mechanisms to relevant internal/external stakeholders. | F6: Clause 7.5 - Documented information | G6: Art. 11/12 - Technical documentation & record-keeping | H6: Governance decisions documented in model risk memos | I6: MRM committee minutes, Jan-Jun 2026 | J6: Memos not indexed or searchable centrally | K6: Low | L6: Stand up central documentation repository | M6: J. Alvarez, Compliance | N6: P3 | O6: Not Started
A7: 5 | B7: Governance & Policy | C7: GOVERN | D7: 1.5 | E7: Ongoing monitoring and periodic independent review of the AI risk management process itself is performed, with clear ownership. | F7: Clause 9.2/9.3 - Internal audit & management review | G7: Art. 17 - Quality management system | H7: Internal audit reviews AI models annually | I7: 2025 Internal Audit Plan | J7: AI risk process itself has not been independently reviewed | K7: Medium | L7: Add AI risk management process to FY27 audit plan | M7: Internal Audit | N7: P3 | O7: Not Started
A8: 6 | B8: Governance & Policy | C8: GOVERN | D8: 1.6 | E8: A current inventory of AI systems in use or development is maintained, tiered by risk level, and resourced accordingly. | F8: Annex A.6.2 - AI system inventory | G8: Art. 6 & Annex III - High-risk classification | H8: Partial inventory exists for customer-facing models only | I8: Model Inventory Q2 2026 | J8: Inventory excludes internal decision-support and vendor AI tools | K8: Critical | L8: Expand inventory to all AI systems org-wide, tiered by risk | M8: R. Osei, Model Risk | N8: P1 | O8: In Progress
A9: 7 | B9: Governance & Policy | C9: GOVERN | D9: 1.7 | E9: Formal processes exist for safe decommissioning and phase-out of AI systems, including data retention/disposal. | F9: Clause 8.1/Annex A.6.2.6 - Decommissioning | G9: Art. 12 - Record-keeping | O9: Not Started
A10: 8 | B10: Governance & Policy | C10: GOVERN | D10: 2.1 | E10: Roles, responsibilities, and communication lines for AI risk mapping/measurement/management are documented and understood by staff. | F10: Clause 5.3 - Roles, responsibilities & authorities | G10: Art. 4 - AI literacy / Art. 26 - Deployer obligations | O10: Not Started
A11: 9 | B11: Governance & Policy | C11: GOVERN | D11: 2.2 | E11: Personnel and teams have the skills, training, and resources needed to fulfill AI governance duties. | F11: Clause 7.2 - Competence | G11: Art. 4 - AI literacy obligation | O11: Not Started
A12: 10 | B12: Governance & Policy | C12: GOVERN | D12: 2.3 | E12: Executive leadership takes explicit accountability for decisions about AI risk and formally accepts residual risk. | F12: Clause 5.1 - Leadership & commitment | G12: Art. 26 - Deployer obligations | O12: Not Started
A13: 11 | B13: Governance & Policy | C13: GOVERN | D13: 3.1 | E13: Decisions on mapping/measuring/managing AI risk draw on demographically and disciplinarily diverse perspectives across the AI lifecycle. | F13: Clause 7.1 - Resources | G13: (Best practice - supports Art. 10 bias mitigation) | O13: Not Started
A14: 12 | B14: Governance & Policy | C14: GOVERN | D14: 3.2 | E14: Policies define and differentiate roles/responsibilities for human-AI teaming configurations and human oversight. | F14: Annex A.9.2 - Human oversight | G14: Art. 14 - Human oversight | O14: Not Started
A15: 13 | B15: Governance & Policy | C15: GOVERN | D15: 4.1 | E15: Organizational risk-management culture treats identification and reporting of AI risk as a shared responsibility, not solely the AI team's. | F15: Clause 5.1 - Leadership & commitment | G15: Art. 26 - Deployer obligations | O15: Not Started
A16: 14 | B16: Governance & Policy | C16: GOVERN | D16: 4.2 | E16: Policies and practices are in place to test, document, and remediate AI system failures, incidents, and negative impacts as they are identified. | F16: Annex A.6.2.8 - Incident response | G16: Art. 73 - Serious incident reporting | O16: Not Started
A17: 15 | B17: Governance & Policy | C17: GOVERN | D17: 4.3 | E17: Organizational practices reward identification and escalation of AI risk (no retaliation for raising concerns). | F17: Clause 5.1 - Leadership & commitment | G17: (Best practice) | O17: Not Started
A18: 16 | B18: Governance & Policy | C18: GOVERN | D18: 5.1 | E18: Processes exist for external stakeholders (customers, regulators, affected individuals) to provide feedback and raise concerns about AI systems. | F18: Annex A.8 - Information for interested parties | G18: Art. 13 - Transparency & Art. 85 - Right to complain | O18: Not Started
A19: 17 | B19: Governance & Policy | C19: GOVERN | D19: 5.2 | E19: Mechanisms allow AI actors to regularly incorporate adjudicated external feedback into system design and operation. | F19: Annex A.6.2.4 - Feedback loops | G19: Art. 72 - Post-market monitoring | O19: Not Started
A20: 18 | B20: Governance & Policy | C20: GOVERN | D20: 6.1 | E20: Policies address AI risks arising from third-party software, data, and pre-trained/foundation models. | F20: Annex A.10 - Third-party & customer relationships | G20: Art. 25 - Responsibilities along the AI value chain | O20: Not Started
... A74: 72 | B74: Risk Treatment (Manage) | C74: MANAGE | D74: 4.3 | E74: Incidents and errors are communicated to all relevant internal AI actors and, where applicable, external authorities within required timeframes. | F74: Annex A.6.2.8 - Incident response | G74: Art. 73 - Serious incident reporting (15-day rule) | O74: Not Started

Sheet EU AI Act Full Assessment
A1: EU AI Act — Full Article-Level Assessment (Verified vs. Regulation (EU) 2024/1689)
A2: # | B2: Chapter / Group | C2: Article | D2: Title | E2: Applies To | F2: Requirement Summary (Paraphrased) | G2: Applicability Date | H2: Current State | I2: Gap Identified | J2: Risk Rating | K2: Priority | L2: Status
A3: 1 | B3: Ch.1 General Provisions | C3: Art. 1 | D3: Subject matter | E3: All | F3: Establishes the Regulation's purpose: harmonised rules for AI, promoting trustworthy AI while protecting health, safety, and fundamental rights. | G3: In force | L3: Not Started
A4: 2 | B4: Ch.1 General Provisions | C4: Art. 2 | D4: Scope | E4: All | F4: Defines who and what the Regulation applies to, including non-EU providers placing systems on the EU market. | G4: In force | L4: Not Started
A5: 3 | B5: Ch.1 General Provisions | C5: Art. 3 | D5: Definitions | E5: All | F5: Defines key terms (AI system, provider, deployer, high-risk, etc.) used throughout the Regulation. | G5: In force | L5: Not Started
A6: 4 | B6: Ch.1 General Provisions | C6: Art. 4 | D6: AI literacy | E6: Providers & Deployers | F6: Requires providers and deployers to ensure staff have sufficient AI literacy to use systems responsibly. | G6: In force (2 Feb 2025) | L6: Not Started
A7: 5 | B7: Ch.2 Prohibited Practices | C7: Art. 5 | D7: Prohibited AI practices | E7: All | F7: Bans unacceptable-risk practices: subliminal manipulation, exploiting vulnerabilities, social scoring, certain biometric categorization/inference, and untargeted facial-recognition scraping. | G7: In force (2 Feb 2025) | L7: Not Started
A8: 6 | B8: Ch.3 High-Risk Classification | C8: Art. 6 | D8: Classification rules for high-risk AI systems | E8: Providers | F8: Sets the two-track test for high-risk status: product-safety-linked systems, and the Annex III use-case list. | G8: Applies 2 Aug 2026 | L8: Not Started
A9: 7 | B9: Ch.3 High-Risk Classification | C9: Art. 7 | D9: Amendments to Annex III | E9: Commission | F9: Allows the Commission to update the high-risk use-case list as risks evolve. | G9: Applies 2 Aug 2026 | L9: Not Started
A10: 8 | B10: Ch.3 Requirements | C10: Art. 8 | D10: Compliance with the requirements | E10: Providers | F10: Requires high-risk systems to comply with Section 2 requirements (Art. 9-15), factoring in intended purpose. | G10: Applies 2 Aug 2026 | L10: Not Started
A11: 9 | B11: Ch.3 Requirements | C11: Art. 9 | D11: Risk management system | E11: Providers | F11: Requires a continuous, iterative risk-management process across the AI system's lifecycle. | G11: Applies 2 Aug 2026 | L11: Not Started
A12: 10 | B12: Ch.3 Requirements | C12: Art. 10 | D12: Data and data governance | E12: Providers | F12: Requires quality criteria for training/validation/test data, including bias examination and mitigation. | G12: Applies 2 Aug 2026 | L12: Not Started
A13: 11 | B13: Ch.3 Requirements | C13: Art. 11 | D13: Technical documentation | E13: Providers | F13: Requires documentation demonstrating compliance, per Annex IV, kept current throughout the lifecycle. | G13: Applies 2 Aug 2026 | L13: Not Started
A14: 12 | B14: Ch.3 Requirements | C14: Art. 12 | D14: Record-keeping | E14: Providers | F14: Requires automatic event logging capability over the system's lifetime. | G14: Applies 2 Aug 2026 | L14: Not Started
... A37: 35 | B37: Ch.12 Penalties | C37: Art. 99 | D37: Penalties | E37: All | F37: Sets administrative fine tiers, up to EUR 35m or 7% of global turnover for prohibited-practice breaches. | G37: Applies 2 Aug 2026 (Art.5 fines from 2 Feb 2025) | L37: Not Started
B39: Note: Article titles and numbers verified against Regulation (EU) 2024/1689 (Official Journal, 13 June 2024). Applicability dates reflect the Act's phased entry-into-force schedule as of assessment date.

Sheet ISO 42001 Full Assessment
A1: ISO/IEC 42001:2023 — Full Clause & Annex A Assessment
A2: # | B2: Clause Group | C2: Sub-Clause / Control | D2: Topic | E2: Requirement Summary (Paraphrased) | F2: Current State | G2: Gap Identified | H2: Risk Rating | I2: Status
A3: 1 | B3: Clause 4 | C3: 4.1 | D3: Understanding the organization and its context | E3: Identify internal/external issues relevant to the AI management system (AIMS) and its intended outcomes. | I3: Not Started
A4: 2 | B4: Clause 4 | C4: 4.2 | D4: Understanding needs and expectations of interested parties | E4: Identify interested parties relevant to the AIMS and their requirements. | I4: Not Started
A5: 3 | B5: Clause 4 | C5: 4.3 | D5: Determining the scope of the AIMS | E5: Define and document the boundaries and applicability of the AIMS. | I5: Not Started
A6: 4 | B6: Clause 4 | C6: 4.4 | D6: AI management system | E6: Establish, implement, maintain, and continually improve the AIMS. | I6: Not Started
A7: 5 | B7: Clause 5 | C7: 5.1 | D7: Leadership and commitment | E7: Top management demonstrates leadership and commitment to the AIMS. | I7: Not Started
A8: 6 | B8: Clause 5 | C8: 5.2 | D8: AI policy | E8: Establish an AI policy appropriate to the organization's purpose. | I8: Not Started
A9: 7 | B9: Clause 5 | C9: 5.3 | D9: Roles, responsibilities and authorities | E9: Assign and communicate responsibilities relevant to the AIMS. | I9: Not Started
A10: 8 | B10: Clause 6 | C10: 6.1 | D10: Actions to address risks and opportunities | E10: Plan actions to address risks/opportunities identified for the AIMS, including AI-specific risk assessment. | I10: Not Started
A11: 9 | B11: Clause 6 | C11: 6.2 | D11: AI objectives and planning to achieve them | E11: Establish measurable AI objectives consistent with the AI policy. | I11: Not Started
A12: 10 | B12: Clause 6 | C12: 6.3 | D12: Planning of changes | E12: Plan changes to the AIMS in a controlled manner. | I12: Not Started
A13: 11 | B13: Clause 7 | C13: 7.1 | D13: Resources | E13: Determine and provide resources needed for the AIMS. | I13: Not Started
A14: 12 | B14: Clause 7 | C14: 7.2 | D14: Competence | E14: Ensure personnel are competent for their AI-related roles. | I14: Not Started
... A35: 33 | B35: Annex A.10 | C35: A.10.2 - A.10.4 | D35: Third-party and customer relationships | E35: Allocate responsibilities with suppliers/customers for AI components and services. | I35: Not Started
B37: Note: Clause and Annex A structure reconstructed from ISO/IEC 42001:2023's published table of contents and control-family topics. ISO standard text is copyrighted — verify exact clause wording against your organization's licensed copy before relying on this for a certification audit.

Sheet Audit Checklist - NIST
A1: Detailed Audit Checklist — NIST AI RMF (151 Testable Questions)
A2: # | B2: Domain | C2: Function | D2: Subcat. | E2: Question Type | F2: Audit Question | G2: ISO 42001 Ref | H2: EU AI Act Ref | I2: Response | J2: Evidence Reviewed | K2: Auditor Notes
A3: 1 | B3: Governance & Policy | C3: GOVERN | D3: 1.1 | E3: Design | F3: Has the organization ensured that legal and regulatory requirements involving AI (incl. sector rules) are identified, tracked, and reflected in policy? | G3: Clause 4.1/4.2 - Context of the organization | H3: Art. 2, Art. 6 & Annex III - Scope & classification
A4: 2 | B4: Governance & Policy | C4: GOVERN | D4: 1.1 | E4: Operating Effectiveness | F4: Can the organization produce evidence (documentation, logs, sign-offs, test results) that this control is functioning in practice, not just documented in policy? [Risk theme: Regulatory] | G4: Clause 4.1/4.2 - Context of the organization | H4: Art. 2, Art. 6 & Annex III - Scope & classification
A5: 3 | B5: Governance & Policy | C5: GOVERN | D5: 1.2 | E5: Design | F5: Has the organization ensured that characteristics of trustworthy AI (valid, reliable, safe, secure, resilient, accountable, transparent, explainable, fair, privacy-enhanced) are embedded into organizational policy and SOPs? | G5: Clause 5.2 - AI Policy | H5: Art. 9 - Risk management system
A6: 4 | B6: Governance & Policy | C6: GOVERN | D6: 1.2 | E6: Operating Effectiveness | F6: Can the organization produce evidence (documentation, logs, sign-offs, test results) that this control is functioning in practice, not just documented in policy? [Risk theme: Trustworthy AI] | G6: Clause 5.2 - AI Policy | H6: Art. 9 - Risk management system
A7: 5 | B7: Governance & Policy | C7: GOVERN | D7: 1.3 | E7: Design | F7: Has the organization ensured that aI risk management processes are integrated into system design, development, deployment, evaluation, and decommissioning, calibrated to organizational risk appetite? | G7: Clause 6.1 - Actions to address risks/opportunities | H7: Art. 9 - Risk management system
A8: 6 | B8: Governance & Policy | C8: GOVERN | D8: 1.3 | E8: Operating Effectiveness | F8: Can the organization produce evidence (documentation, logs, sign-offs, test results) that this control is functioning in practice, not just documented in policy? [Risk theme: Lifecycle Governance] | G8: Clause 6.1 - Actions to address risks/opportunities | H8: Art. 9 - Risk management system
A9: 7 | B9: Governance & Policy | C9: GOVERN | D9: 1.4 | E9: Design | F9: Has the organization ensured that risk management processes and outcomes are documented and made available through transparency mechanisms to relevant internal/external stakeholders? | G9: Clause 7.5 - Documented information | H9: Art. 11/12 - Technical documentation & record-keeping
A10: 8 | B10: Governance & Policy | C10: GOVERN | D10: 1.4 | E10: Operating Effectiveness | F10: Can the organization produce evidence (documentation, logs, sign-offs, test results) that this control is functioning in practice, not just documented in policy? [Risk theme: Transparency] | G10: Clause 7.5 - Documented information | H10: Art. 11/12 - Technical documentation & record-keeping
A11: 9 | B11: Governance & Policy | C11: GOVERN | D11: 1.5 | E11: Design | F11: Has the organization ensured that ongoing monitoring and periodic independent review of the AI risk management process itself is performed, with clear ownership? | G11: Clause 9.2/9.3 - Internal audit & management review | H11: Art. 17 - Quality management system
A12: 10 | B12: Governance & Policy | C12: GOVERN | D12: 1.5 | E12: Operating Effectiveness | F12: Can the organization produce evidence (documentation, logs, sign-offs, test results) that this control is functioning in practice, not just documented in policy? [Risk theme: Oversight] | G12: Clause 9.2/9.3 - Internal audit & management review | H12: Art. 17 - Quality management system
A13: 11 | B13: Governance & Policy | C13: GOVERN | D13: 1.6 | E13: Design | F13: Has the organization ensured that a current inventory of AI systems in use or development is maintained, tiered by risk level, and resourced accordingly? | G13: Annex A.6.2 - AI system inventory | H13: Art. 6 & Annex III - High-risk classification
A14: 12 | B14: Governance & Policy | C14: GOVERN | D14: 1.6 | E14: Operating Effectiveness | F14: Can the organization produce evidence (documentation, logs, sign-offs, test results) that this control is functioning in practice, not just documented in policy? [Risk theme: AI Inventory] | G14: Annex A.6.2 - AI system inventory | H14: Art. 6 & Annex III - High-risk classification
... A153: 151 | B153: Risk Treatment (Manage) | C153: MANAGE | D153: 4.3 | E153: Deep-Dive | F153: Has the 'communicate incidents' process been tested (e.g., a tabletop exercise), or does it exist only as an untested policy document? | G153: Annex A.6.2.8 - Incident response | H153: Art. 73 - Serious incident reporting (15-day rule)

Sheet Audit Checklist - EU AI Act
A1: Detailed Audit Checklist — EU AI Act (114 Testable Questions)
A2: # | B2: Chapter/Group | C2: Article | D2: Title | E2: Question Type | F2: Audit Question | G2: Applies To | H2: Applicability | I2: Response | J2: Evidence Reviewed | K2: Auditor Notes
A3: 1 | B3: Ch.1 General Provisions | C3: Art. 1 | D3: Subject matter | E3: Context (Non-Actionable) | F3: Establishes the Regulation's purpose: harmonised rules for AI, promoting trustworthy AI while protecting health, safety, and fundamental rights. (Definitional/scope article — no standalone compliance action required; relevant only as context for other obligations.) | G3: All | H3: In force
A4: 2 | B4: Ch.1 General Provisions | C4: Art. 2 | D4: Scope | E4: Context (Non-Actionable) | F4: Defines who and what the Regulation applies to, including non-EU providers placing systems on the EU market. (Definitional/scope article — no standalone compliance action required; relevant only as context for other obligations.) | G4: All | H4: In force
A5: 3 | B5: Ch.1 General Provisions | C5: Art. 3 | D5: Definitions | E5: Context (Non-Actionable) | F5: Defines key terms (AI system, provider, deployer, high-risk, etc.) used throughout the Regulation. (Definitional/scope article — no standalone compliance action required; relevant only as context for other obligations.) | G5: All | H5: In force
A6: 4 | B6: Ch.1 General Provisions | C6: Art. 4 | D6: AI literacy | E6: Design | F6: Has the organization implemented controls addressing this obligation under Art. 4: Requires providers and deployers to ensure staff have sufficient AI literacy to use systems responsibly? | G6: Providers & Deployers | H6: In force (2 Feb 2025)
A7: 5 | B7: Ch.1 General Provisions | C7: Art. 4 | D7: AI literacy | E7: Evidence | F7: Is there documented evidence (technical documentation, logs, declarations, or records) available to demonstrate compliance with Art. 4, if requested by a market surveillance authority? | G7: Providers & Deployers | H7: In force (2 Feb 2025)
A8: 6 | B8: Ch.1 General Provisions | C8: Art. 4 | D8: AI literacy | E8: Ownership | F8: Is a specific role or function accountable for maintaining ongoing compliance with Art. 4 as the applicability date (In force (2 Feb 2025)) approaches or passes? | G8: Providers & Deployers | H8: In force (2 Feb 2025)
A9: 7 | B9: Ch.2 Prohibited Practices | C9: Art. 5 | D9: Prohibited AI practices | E9: Design | F9: Has the organization implemented controls addressing this obligation under Art. 5: Bans unacceptable-risk practices: subliminal manipulation, exploiting vulnerabilities, social scoring, certain biometric categorization/inference, and untargeted facial-recognition scraping? | G9: All | H9: In force (2 Feb 2025)
A10: 8 | B10: Ch.2 Prohibited Practices | C10: Art. 5 | D10: Prohibited AI practices | E10: Evidence | F10: Is there documented evidence (technical documentation, logs, declarations, or records) available to demonstrate compliance with Art. 5, if requested by a market surveillance authority? | G10: All | H10: In force (2 Feb 2025)
A11: 9 | B11: Ch.2 Prohibited Practices | C11: Art. 5 | D11: Prohibited AI practices | E11: Ownership | F11: Is a specific role or function accountable for maintaining ongoing compliance with Art. 5 as the applicability date (In force (2 Feb 2025)) approaches or passes? | G11: All | H11: In force (2 Feb 2025)
A12: 10 | B12: Ch.3 High-Risk Classification | C12: Art. 6 | D12: Classification rules for high-risk AI systems | E12: Design | F12: Has the organization implemented controls addressing this obligation under Art. 6: Sets the two-track test for high-risk status: product-safety-linked systems, and the Annex III use-case list? | G12: Providers | H12: Applies 2 Aug 2026
A13: 11 | B13: Ch.3 High-Risk Classification | C13: Art. 6 | D13: Classification rules for high-risk AI systems | E13: Evidence | F13: Is there documented evidence (technical documentation, logs, declarations, or records) available to demonstrate compliance with Art. 6, if requested by a market surveillance authority? | G13: Providers | H13: Applies 2 Aug 2026
A14: 12 | B14: Ch.3 High-Risk Classification | C14: Art. 6 | D14: Classification rules for high-risk AI systems | E14: Ownership | F14: Is a specific role or function accountable for maintaining ongoing compliance with Art. 6 as the applicability date (Applies 2 Aug 2026) approaches or passes? | G14: Providers | H14: Applies 2 Aug 2026
... A108: 106 | B108: Ch.12 Penalties | C108: Art. 99 | D108: Penalties | E108: Deep-Dive | F108: Has leadership been briefed on the specific fine exposure (up to EUR 35m / 7% of global turnover for Art. 5 breaches) tied to this system's risk classification? | G108: All | H108: Applies 2 Aug 2026 (Art.5 fines from 2 Feb 2025)

Sheet Audit Checklist - ISO 42001
A1: Detailed Audit Checklist — ISO/IEC 42001 (104 Testable Questions)
A2: # | B2: Clause Group | C2: Sub-Clause | D2: Topic | E2: Question Type | F2: Audit Question | G2: Response | H2: Evidence Reviewed | I2: Auditor Notes
A3: 1 | B3: Clause 4 | C3: 4.1 | D3: Understanding the organization and its context | E3: Design | F3: Has the organization ensured that identify internal/external issues relevant to the AI management system (AIMS) and its intended outcomes?
A4: 2 | B4: Clause 4 | C4: 4.1 | D4: Understanding the organization and its context | E4: Evidence | F4: Can the organization produce documented information (per Clause 7.5) demonstrating this is implemented, not just described in policy?
A5: 3 | B5: Clause 4 | C5: 4.1 | D5: Understanding the organization and its context | E5: Review | F5: Has this been covered by internal audit (Clause 9.2) or management review (Clause 9.3) within the last 12 months?
A6: 4 | B6: Clause 4 | C6: 4.2 | D6: Understanding needs and expectations of interested parties | E6: Design | F6: Has the organization ensured that identify interested parties relevant to the AIMS and their requirements?
A7: 5 | B7: Clause 4 | C7: 4.2 | D7: Understanding needs and expectations of interested parties | E7: Evidence | F7: Can the organization produce documented information (per Clause 7.5) demonstrating this is implemented, not just described in policy?
A8: 6 | B8: Clause 4 | C8: 4.2 | D8: Understanding needs and expectations of interested parties | E8: Review | F8: Has this been covered by internal audit (Clause 9.2) or management review (Clause 9.3) within the last 12 months?
A9: 7 | B9: Clause 4 | C9: 4.3 | D9: Determining the scope of the AIMS | E9: Design | F9: Has the organization ensured that define and document the boundaries and applicability of the AIMS?
A10: 8 | B10: Clause 4 | C10: 4.3 | D10: Determining the scope of the AIMS | E10: Evidence | F10: Can the organization produce documented information (per Clause 7.5) demonstrating this is implemented, not just described in policy?
A11: 9 | B11: Clause 4 | C11: 4.3 | D11: Determining the scope of the AIMS | E11: Review | F11: Has this been covered by internal audit (Clause 9.2) or management review (Clause 9.3) within the last 12 months?
A12: 10 | B12: Clause 4 | C12: 4.4 | D12: AI management system | E12: Design | F12: Has the organization ensured that establish, implement, maintain, and continually improve the AIMS?
A13: 11 | B13: Clause 4 | C13: 4.4 | D13: AI management system | E13: Evidence | F13: Can the organization produce documented information (per Clause 7.5) demonstrating this is implemented, not just described in policy?
A14: 12 | B14: Clause 4 | C14: 4.4 | D14: AI management system | E14: Review | F14: Has this been covered by internal audit (Clause 9.2) or management review (Clause 9.3) within the last 12 months?
... A106: 104 | B106: Clause 9 | C106: 9.2 | D106: Internal audit | E106: Deep-Dive | F106: Has an internal auditor independent of the AI development team reviewed this control within the last audit cycle?

Sheet Responsible AI
A1: Responsible AI Principles Checklist | I1: % Yes/Complete: | J1: =IFERROR((COUNTIF(D3:D20,"Yes")+0.5*COUNTIF(D3:D20,"Partial"))/(COUNTA(D3:D20)-COUNTIF(D3:D20,"N/A")),0) -> 0
A2: # | B2: Principle | C2: Checklist Question | D2: Response | E2: Evidence Reviewed | F2: Owner | G2: Notes
A3: 1 | B3: Fairness | C3: Has the AI system been tested for disparate impact across protected classes, with a defined acceptable-threshold and documented results?
A4: 2 | B4: Fairness | C4: Is there a remediation process if a fairness metric breaches threshold post-deployment?
A5: 3 | B5: Transparency | C5: Are end users or affected individuals informed that a decision affecting them was made or assisted by AI?
A6: 4 | B6: Transparency | C6: Is there a plain-language notice describing what the AI system does and its limitations?
A7: 5 | B7: Explainability | C7: Can the organization produce a reason code or explanation for an individual adverse AI-assisted decision on request?
A8: 6 | B8: Explainability | C8: Is the explanation method appropriate to the audience (technical explanation for auditors vs. plain-language for consumers)?
A9: 7 | B9: Accountability | C9: Is a named individual (not just 'the team') accountable for this AI system's outcomes end-to-end?
A10: 8 | B10: Accountability | C10: Is that accountability reflected in a job description, RACI, or governance charter?
A11: 9 | B11: Privacy | C11: Has a privacy impact assessment been completed for personal data used to train or run this system?
A12: 10 | B12: Privacy | C12: Are privacy-enhancing techniques (minimization, anonymization, differential privacy) applied where feasible?
A13: 11 | B13: Security | C13: Has the AI system undergone adversarial/security testing appropriate to its risk tier?
A14: 12 | B14: Security | C14: Are model artifacts and training data access-controlled and logged?
... A20: 18 | B20: Inclusiveness | C20: Have potentially impacted user groups outside the primary target population been identified and considered?

Sheet Guardrails - Foundational
A1: Guardrails — Foundational Checklist | I1: % Yes/Complete: | J1: =IFERROR((COUNTIF(D3:D18,"Yes")+0.5*COUNTIF(D3:D18,"Partial"))/(COUNTA(D3:D18)-COUNTIF(D3:D18,"N/A")),0) -> 0
A2: # | B2: Guardrail Layer | C2: Checklist Question | D2: Response | E2: Evidence Reviewed | F2: Owner | G2: Notes
A3: 1 | B3: Input Guardrails | C3: Is there prompt-injection / adversarial-input protection for any generative AI system accepting free-text input?
A4: 2 | B4: Input Guardrails | C4: Is PII in inbound requests detected and handled per data policy before reaching the model?
A5: 3 | B5: Input Guardrails | C5: Is uploaded file content (if applicable) validated for type, size, and malicious content before processing?
A6: 4 | B6: Input Guardrails | C6: Is there rate limiting to prevent abuse or unintended scale of use?
A7: 5 | B7: Model Guardrails | C7: Is there a toxicity/harmful-content filter appropriate to the system's audience?
A8: 6 | B8: Model Guardrails | C8: Are confidence thresholds defined below which the system defers to a human rather than auto-deciding?
A9: 7 | B9: Model Guardrails | C9: Is there a safety classifier or secondary check layer for high-stakes outputs?
A10: 8 | B10: Output Guardrails | C10: For generative outputs used in decisions, are citations or source references required and checked?
A11: 9 | B11: Output Guardrails | C11: Is there a hallucination/factuality check appropriate to the use case's risk level?
A12: 10 | B12: Output Guardrails | C12: Is outbound content moderated before being shown to end users or used downstream?
A13: 11 | B13: Output Guardrails | C13: Is PII masked or redacted in outputs where appropriate?
A14: 12 | B14: Operational Guardrails | C14: Is access to the AI system and its administration console governed by role-based access control (RBAC)?
... A18: 16 | B18: Operational Guardrails | C18: Are incident alerts routed to a specific on-call owner with a defined response SLA?

Sheet Guardrails - Technical
A1: AI Technical Guardrails — Input / Model / Output / Operational (36 Controls) | I1: % Yes/Complete: | J1: =IFERROR((COUNTIF(D3:D38,"Yes")+0.5*COUNTIF(D3:D38,"Partial"))/(COUNTA(D3:D38)-COUNTIF(D3:D38,"N/A")),0) -> 0
A2: # | B2: Guardrail Layer | C2: Audit Question | D2: Response | E2: Evidence Reviewed | F2: Owner | G2: Auditor Notes
A3: 1 | B3: Input — Prompt injection detection | C3: Are inbound prompts screened for injection/jailbreak patterns before reaching the model?
A4: 2 | B4: Input — Prompt/input validation | C4: Is free-text input validated against expected format, length, and schema before processing?
A5: 3 | B5: Input — PII detection on input | C5: Is inbound PII detected and handled per data policy before it reaches the model or is logged?
A6: 4 | B6: Input — Malware / file scanning | C6: Are uploaded files scanned for malware before processing?
A7: 5 | B7: Input — File type & size validation | C7: Are uploaded files validated for allowed type, size, and structure?
A8: 6 | B8: Input — Injection protection (SQL/command) | C8: Where AI output feeds downstream systems, is it sanitized against SQL/command injection?
A9: 7 | B9: Input — Rate limiting / throttling | C9: Is per-user and per-system rate limiting enforced to prevent abuse or runaway cost?
A10: 8 | B10: Input — Input provenance / source authentication | C10: Is the source of inbound requests authenticated so anonymous or spoofed traffic is controlled?
A11: 9 | B11: Input — Context/grounding data validation | C11: For RAG systems, is retrieved context validated for freshness and authorization before use?
A12: 10 | B12: Model — Safety classifier | C12: Is a safety/harm classifier applied to model behavior appropriate to the audience?
A13: 11 | B13: Model — Confidence threshold gating | C13: Below a defined confidence threshold, does the system defer to a human rather than auto-decide?
A14: 12 | B14: Model — Hallucination / factuality check | C14: Is there a factuality or grounding check for generative outputs used in decisions?
... A38: 36 | B38: Operational — Segregation of duties | C38: Are development, approval, and production-deployment duties segregated?
A40: Note: Controls reflect current AI/LLM guardrail practice. Applicability depends on system type — a traditional ML scoring model won't need prompt-injection controls; a generative system will. Mark non-applicable controls 'N/A' with a note.

Sheet GenAI Controls
A1: GenAI & Agentic AI — Specific Controls | I1: % Yes/Complete: | J1: =IFERROR((COUNTIF(D3:D20,"Yes")+0.5*COUNTIF(D3:D20,"Partial"))/(COUNTA(D3:D20)-COUNTIF(D3:D20,"N/A")),0) -> 0
A2: # | B2: Category | C2: Control Question | D2: Response | E2: Evidence Reviewed | F2: Owner | G2: Notes
A3: 1 | B3: Prompt Security | C3: Is prompt-injection detection applied to all free-text inputs?
A4: 2 | B4: Prompt Security | C4: Is jailbreak/guardrail-bypass detection in place?
A5: 3 | B5: Prompt Security | C5: Is sensitive-prompt detection applied (e.g., attempts to extract secrets or PII)?
A6: 4 | B6: Prompt Security | C6: Are prompts logged for audit and abuse investigation (with privacy controls)?
A7: 5 | B7: Context / Grounding | C7: For RAG, is retrieved context validated for authorization and freshness before use?
A8: 6 | B8: Context / Grounding | C8: Is retrieval grounding enforced so responses cite approved sources?
A9: 7 | B9: Context / Grounding | C9: Are context-window limits enforced to control cost and manipulation surface?
A10: 8 | B10: Output Integrity | C10: Is citation/source verification performed on generative outputs used in decisions?
A11: 9 | B11: Output Integrity | C11: Is hallucination/factuality checking applied appropriate to risk?
A12: 10 | B12: Output Integrity | C12: Is output content moderated before reaching users or downstream systems?
A13: 11 | B13: Model Routing | C13: Is model routing governed (which model serves which use case) with approval?
A14: 12 | B14: Model Routing | C14: Is there fallback behavior if the primary model is unavailable or low-confidence?
... A20: 18 | B20: Cost & Abuse | C20: Is anomalous usage/cost spike detected and alerted?
A22: Note: Applies to generative and agentic AI systems. Mark 'N/A' for traditional ML systems where a control doesn't apply.

Sheet Data Governance
A1: Data Governance for AI (15 Controls) | I1: % Yes/Complete: | J1: =IFERROR((COUNTIF(D3:D17,"Yes")+0.5*COUNTIF(D3:D17,"Partial"))/(COUNTA(D3:D17)-COUNTIF(D3:D17,"N/A")),0) -> 0
A2: # | B2: Data Domain | C2: Audit Question | D2: Response | E2: Evidence Reviewed | F2: Owner | G2: Auditor Notes
A3: 1 | B3: Data Quality | C3: Is training/production data quality (accuracy, completeness, representativeness) monitored on an ongoing basis, not just at build time?
A4: 2 | B4: Data Quality | C4: Are data quality thresholds defined, with alerts when breached?
A5: 3 | B5: Data Lineage | C5: Is end-to-end data lineage documented from source through to model training and inference?
A6: 4 | B6: Data Lineage | C6: Can the organization trace which dataset version trained a given production model?
A7: 5 | B7: Metadata Management | C7: Is metadata (source, collection date, schema, sensitivity) maintained for datasets used in AI?
A8: 6 | B8: PII / Sensitive Data | C8: Is personal and sensitive data classified and tracked wherever it flows through AI pipelines?
A9: 7 | B9: PII / Sensitive Data | C9: Are special-category / regulated data types subject to additional controls before AI use?
A10: 8 | B10: Consent & Lawful Basis | C10: Where personal data is used, is there a documented lawful basis or consent record?
A11: 9 | B11: Consent & Lawful Basis | C11: Can consent withdrawal be honored in training/inference data where required?
A12: 10 | B12: Retention & Disposal | C12: Are data retention and secure-disposal schedules defined and enforced for AI data?
A13: 11 | B13: Feature Store Governance | C13: Is the feature store (if used) governed for access, versioning, and quality?
A14: 12 | B14: Data Ownership | C14: Is a data owner assigned for each dataset feeding a production AI system?
... A17: 15 | B17: Data Residency | C17: Is data residency for AI processing confirmed against applicable regulatory requirements?

Sheet Model Governance
A1: Model Governance & Model Risk (14 Controls) | I1: % Yes/Complete: | J1: =IFERROR((COUNTIF(D3:D16,"Yes")+0.5*COUNTIF(D3:D16,"Partial"))/(COUNTA(D3:D16)-COUNTIF(D3:D16,"N/A")),0) -> 0
A2: # | B2: Model Domain | C2: Audit Question | D2: Response | E2: Evidence Reviewed | F2: Owner | G2: Auditor Notes
A3: 1 | B3: Model Cards | C3: Does each production model have a model card documenting purpose, data, performance, and limitations?
A4: 2 | B4: Model Registry / Inventory | C4: Is there a central model registry covering all production AI systems with risk tier?
A5: 3 | B5: Model Registry / Inventory | C5: Does the registry include third-party / vendor and embedded models, not just in-house builds?
A6: 4 | B6: Version Control | C6: Is model version control in place, identifying exactly which version produced a given decision?
A7: 5 | B7: Champion / Challenger | C7: Is there a champion/challenger or A-B process before promoting a new model version?
A8: 6 | B8: Model Approval | C8: Is there a formal go/no-go approval gate before a model enters production?
A9: 7 | B9: Independent Validation | C9: Are models independently validated (conceptual soundness, ongoing monitoring, outcomes analysis) by a party separate from the developer?
A10: 8 | B10: Drift Thresholds | C10: Are performance/drift thresholds defined that trigger revalidation or retraining?
A11: 9 | B11: Retraining | C11: Is retraining governed by a defined cadence or trigger rather than ad hoc?
A12: 10 | B12: Model Monitoring | C12: Is production model performance monitored continuously against defined KPIs?
